Workbook

Sheet Sheet1
A1: JOB ID | B1: JOB TITLE | C1: COMPANY NAME | D1: INDUSTRY | E1: JOB TYPE | F1: WORK MODE | G1: POSTED DATE | H1: COUNTRY | I1: STATE | J1: CITY | K1: SALARY MIN | L1: SALARY MAX | M1: SKILLS | N1: EXPERIENCE LEVEL | O1: JOB SOURCE
A2: 17850 | B2: DATA ANALYST | C2: ALPHA TECHNOLOGIES | D2: =IFERROR(INDEX(Sheet2!$B$2:$B$1132,MATCH(Sheet1!C2,Sheet1!$C$2:$C$1132,0)),"IDK") -> IT | E2: FULL-TIME | F2: WORK FROM OFFICE | G2: 45433 | H2: UNITED STATES | I2: California | J2: San Francisco | K2: =IFERROR(INDEX(Sheet2!$C$2:$C$1132,MATCH(Sheet1!C2,Sheet1!$C$2:$C$1132,0)),"") -> 35000 | L2: =IFERROR(INDEX(Sheet2!$D$2:$D$1132,MATCH(Sheet1!C2,$C$2:$C$1132,0)),"") -> 70000 | M2: SQL, EXCEL, POWERBI, TABLEAU | N2: ENTRY-LEVEL | O2: LINKEDIN
A3: 17851 | B3: DATA ENGINEER | C3: CSV HEALTH | D3: =IFERROR(INDEX(Sheet2!$B$2:$B$1132,MATCH(Sheet1!C3,Sheet1!$C$2:$C$1132,0)),"IDK") -> HEALTH | E3: FULL-TIME | F3: WORK FROM OFFICE | G3: 45337 | H3: UNITED STATES | I3: California | J3: San Jose | K3: =IFERROR(INDEX(Sheet2!$C$2:$C$1132,MATCH(Sheet1!C3,Sheet1!$C$2:$C$1132,0)),"") -> 25000 | L3: =IFERROR(INDEX(Sheet2!$D$2:$D$1132,MATCH(Sheet1!C3,$C$2:$C$1132,0)),"") -> 50000 | M3: SQL, PYTHON, AWS, SPARK, ETL | N3: ENTRY-LEVEL | O3: GLASSDOOR
A4: 17852 | B4: DATA SCIENTIST | C4: FACEBOOK | D4: =IFERROR(INDEX(Sheet2!$B$2:$B$1132,MATCH(Sheet1!C4,Sheet1!$C$2:$C$1132,0)),"IDK") -> SOCIAL | E4: FULL-TIME | F4: WORK FROM OFFICE | G4: 45528 | H4: UNITED STATES | I4: California | J4: Los Angeles | K4: =IFERROR(INDEX(Sheet2!$C$2:$C$1132,MATCH(Sheet1!C4,Sheet1!$C$2:$C$1132,0)),"") -> 30000 | L4: =IFERROR(INDEX(Sheet2!$D$2:$D$1132,MATCH(Sheet1!C4,$C$2:$C$1132,0)),"") -> 60000 | M4: PYTHON, MACHINE LEARNING,PANDAS, NUMPY | N4: ENTRY-LEVEL | O4: GLASSDOOR
A5: 17853 | B5: BUSINESS ANALYST | C5: STIER SOLUTIONS | D5: =IFERROR(INDEX(Sheet2!$B$2:$B$1132,MATCH(Sheet1!C5,Sheet1!$C$2:$C$1132,0)),"IDK") -> FINANCE | E5: FULL-TIME | F5: WORK FROM OFFICE | G5: 45628 | H5: UNITED STATES | I5: New York | J5: New York City | K5: =IFERROR(INDEX(Sheet2!$C$2:$C$1132,MATCH(Sheet1!C5,Sheet1!$C$2:$C$1132,0)),"") -> 35000 | L5: =IFERROR(INDEX(Sheet2!$D$2:$D$1132,MATCH(Sheet1!C5,$C$2:$C$1132,0)),"") -> 75000 | M5: EXCEL, SQL, TABLEAU, BUSINESS ANALYSIS | N5: ENTRY-LEVEL | O5: GLASSDOOR
A6: 17854 | B6: FINANCIAL ANALYST | C6: OPTUM | D6: =IFERROR(INDEX(Sheet2!$B$2:$B$1132,MATCH(Sheet1!C6,Sheet1!$C$2:$C$1132,0)),"IDK") -> IT | E6: FULL-TIME | F6: WORK FROM OFFICE | G6: 45314 | H6: UNITED STATES | I6: Texas | J6: Austin | K6: =IFERROR(INDEX(Sheet2!$C$2:$C$1132,MATCH(Sheet1!C6,Sheet1!$C$2:$C$1132,0)),"") -> 40000 | L6: =IFERROR(INDEX(Sheet2!$D$2:$D$1132,MATCH(Sheet1!C6,$C$2:$C$1132,0)),"") -> 80000 | M6: EXCEL, SQL, FINANCIAL MODELLING, BUDGETING | N6: ENTRY-LEVEL | O6: NAUKARI
A7: 17855 | B7: CYBER SECURITY | C7: TECUMEN LIMITED | D7: =IFERROR(INDEX(Sheet2!$B$2:$B$1132,MATCH(Sheet1!C7,Sheet1!$C$2:$C$1132,0)),"IDK") -> IT | E7: FULL-TIME | F7: WORK FROM OFFICE | G7: 45424 | H7: UNITED STATES | I7: Texas | J7: Dallas | K7: =IFERROR(INDEX(Sheet2!$C$2:$C$1132,MATCH(Sheet1!C7,Sheet1!$C$2:$C$1132,0)),"") -> 30000 | L7: =IFERROR(INDEX(Sheet2!$D$2:$D$1132,MATCH(Sheet1!C7,$C$2:$C$1132,0)),"") -> 55000 | M7: NETWORK SECURITY, ETHICAL HACKING, RISK ASSESSMENT | N7: ENTRY-LEVEL | O7: LINKEDIN
A8: 17856 | B8: AI/ML ENGINEER | C8: MINDSPACE | D8: =IFERROR(INDEX(Sheet2!$B$2:$B$1132,MATCH(Sheet1!C8,Sheet1!$C$2:$C$1132,0)),"IDK") -> IT | E8: FULL-TIME | F8: WORK FROM OFFICE | G8: 45442 | H8: UNITED STATES | I8: Texas | J8: Houston | K8: =IFERROR(INDEX(Sheet2!$C$2:$C$1132,MATCH(Sheet1!C8,Sheet1!$C$2:$C$1132,0)),"") -> 35000 | L8: =IFERROR(INDEX(Sheet2!$D$2:$D$1132,MATCH(Sheet1!C8,$C$2:$C$1132,0)),"") -> 70000 | M8: CLOUD, NETWORK, MACHINE LEARNING | N8: ENTRY-LEVEL | O8: NAUKARI
A9: 17857 | B9: RISK MANAGEMENT | C9: SKILLFIED SOLUTIONS | D9: =IFERROR(INDEX(Sheet2!$B$2:$B$1132,MATCH(Sheet1!C9,Sheet1!$C$2:$C$1132,0)),"IDK") -> IT | E9: FULL-TIME | F9: WORK FROM OFFICE | G9: 45425 | H9: UNITED STATES | I9: Washington | J9: Seattle | K9: =IFERROR(INDEX(Sheet2!$C$2:$C$1132,MATCH(Sheet1!C9,Sheet1!$C$2:$C$1132,0)),"") -> 25000 | L9: =IFERROR(INDEX(Sheet2!$D$2:$D$1132,MATCH(Sheet1!C9,$C$2:$C$1132,0)),"") -> 60000 | M9: RISK ANALYSIS, DATA ANALYSIS, EXCEL, STATISTICS | N9: MID-LEVEL | O9: INDEED
A10: 17858 | B10: MARKETING MANAGER | C10: MACROS PVT LTD | D10: =IFERROR(INDEX(Sheet2!$B$2:$B$1132,MATCH(Sheet1!C10,Sheet1!$C$2:$C$1132,0)),"IDK") -> IT | E10: FULL-TIME | F10: WORK FROM OFFICE | G10: 45454 | H10: UNITED STATES | I10: Massachusetts | J10: Boston | K10: =IFERROR(INDEX(Sheet2!$C$2:$C$1132,MATCH(Sheet1!C10,Sheet1!$C$2:$C$1132,0)),"") -> 25000 | L10: =IFERROR(INDEX(Sheet2!$D$2:$D$1132,MATCH(Sheet1!C10,$C$2:$C$1132,0)),"") -> 75000 | M10: GOOGLE ANALYTICS, SEO, SOCIAL MEDIA ANALYTICS, EXCEL | N10: MID-LEVEL | O10: LINKEDIN
A11: 17859 | B11: RISK MANAGEMENT | C11: INFROSOFT | D11: =IFERROR(INDEX(Sheet2!$B$2:$B$1132,MATCH(Sheet1!C11,Sheet1!$C$2:$C$1132,0)),"IDK") -> SOCIAL | E11: FULL-TIME | F11: WORK FROM OFFICE | G11: 45490 | H11: UNITED STATES | I11: Illinois | J11: Chicago | K11: =IFERROR(INDEX(Sheet2!$C$2:$C$1132,MATCH(Sheet1!C11,Sheet1!$C$2:$C$1132,0)),"") -> 20000 | L11: =IFERROR(INDEX(Sheet2!$D$2:$D$1132,MATCH(Sheet1!C11,$C$2:$C$1132,0)),"") -> 70000 | M11: RISK ANALYSIS, DATA ANALYSIS, EXCEL | N11: MID-LEVEL | O11: NAUKARI
A12: 17860 | B12: BUSINESS ANALYST | C12: INFRATECH LTD | D12: =IFERROR(INDEX(Sheet2!$B$2:$B$1132,MATCH(Sheet1!C12,Sheet1!$C$2:$C$1132,0)),"IDK") -> FINANCE | E12: FULL-TIME | F12: WORK FROM OFFICE | G12: 45568 | H12: UNITED STATES | I12: Georgia | J12: Atlanta | K12: =IFERROR(INDEX(Sheet2!$C$2:$C$1132,MATCH(Sheet1!C12,Sheet1!$C$2:$C$1132,0)),"") -> 40000 | L12: =IFERROR(INDEX(Sheet2!$D$2:$D$1132,MATCH(Sheet1!C12,$C$2:$C$1132,0)),"") -> 85000 | M12: SQL,EXCEL, BUSINESS ANALYSIS | N12: ENTRY-LEVEL | O12: INDEED
A13: 17861 | B13: FINANCIAL ANALYST | C13: SCALE AI SOLUTIONS | D13: =IFERROR(INDEX(Sheet2!$B$2:$B$1132,MATCH(Sheet1!C13,Sheet1!$C$2:$C$1132,0)),"IDK") -> IT | E13: FULL-TIME | F13: WORK FROM OFFICE | G13: 45654 | H13: UNITED STATES | I13: North Carolina | J13: Raleigh | K13: =IFERROR(INDEX(Sheet2!$C$2:$C$1132,MATCH(Sheet1!C13,Sheet1!$C$2:$C$1132,0)),"") -> 35000 | L13: =IFERROR(INDEX(Sheet2!$D$2:$D$1132,MATCH(Sheet1!C13,$C$2:$C$1132,0)),"") -> 90000 | M13: FINANCIAL ANALYSIS,EXCEL,BUDGETING | N13: MID-LEVEL | O13: MONSTER
A14: 17862 | B14: CYBER SECURITY | C14: SPECTRUM | D14: =IFERROR(INDEX(Sheet2!$B$2:$B$1132,MATCH(Sheet1!C14,Sheet1!$C$2:$C$1132,0)),"IDK") -> SOCIAL | E14: FULL-TIME | F14: WORK FROM OFFICE | G14: 45402 | H14: UNITED STATES | I14: Virginia | J14: Arlington | K14: =IFERROR(INDEX(Sheet2!$C$2:$C$1132,MATCH(Sheet1!C14,Sheet1!$C$2:$C$1132,0)),"") -> 30000 | L14: =IFERROR(INDEX(Sheet2!$D$2:$D$1132,MATCH(Sheet1!C14,$C$2:$C$1132,0)),"") -> 95000 | M14: ETHICAL HACKING, NETWORK SECURITY,OPEARTIONAL MANGEMENT | N14: HIGH-LEVEL | O14: GLASSDOOR
A15: 17863 | B15: DATA SCIENTIST | C15: GOOD SPACE AI | D15: =IFERROR(INDEX(Sheet2!$B$2:$B$1132,MATCH(Sheet1!C15,Sheet1!$C$2:$C$1132,0)),"IDK") -> IT | E15: FULL-TIME | F15: WORK FROM OFFICE | G15: 45433 | H15: UNITED STATES | I15: Florida | J15: Miami | K15: =IFERROR(INDEX(Sheet2!$C$2:$C$1132,MATCH(Sheet1!C15,Sheet1!$C$2:$C$1132,0)),"") -> 50000 | L15: =IFERROR(INDEX(Sheet2!$D$2:$D$1132,MATCH(Sheet1!C15,$C$2:$C$1132,0)),"") -> 100000 | M15: =IFERROR(INDEX($M$2:$M$1132,MATCH(B15,$B$2:$B$1132,0)),"") -> PYTHON, MACHINE LEARNING,PANDAS, NUMPY | N15: HIGH-LEVEL | O15: INDEED
A16: 17864 | B16: BUSINESS ANALYST | C16: OPTUM | D16: =IFERROR(INDEX(Sheet2!$B$2:$B$1132,MATCH(Sheet1!C16,Sheet1!$C$2:$C$1132,0)),"IDK") -> IT | E16: FULL-TIME | F16: WORK FROM OFFICE | G16: 45537 | H16: UNITED STATES | I16: Texas | J16: Dallas | K16: =IFERROR(INDEX(Sheet2!$C$2:$C$1132,MATCH(Sheet1!C16,Sheet1!$C$2:$C$1132,0)),"") -> 40000 | L16: =IFERROR(INDEX(Sheet2!$D$2:$D$1132,MATCH(Sheet1!C16,$C$2:$C$1132,0)),"") -> 80000 | M16: =IFERROR(INDEX($M$2:$M$1132,MATCH(B16,$B$2:$B$1132,0)),"") -> EXCEL, SQL, TABLEAU, BUSINESS ANALYSIS | N16: HIGH-LEVEL | O16: LINKEDIN
A17: 17865 | B17: DATA ANALYST | C17: TECUMEN LIMITED | D17: =IFERROR(INDEX(Sheet2!$B$2:$B$1132,MATCH(Sheet1!C17,Sheet1!$C$2:$C$1132,0)),"IDK") -> IT | E17: FULL-TIME | F17: WORK FROM OFFICE | G17: 45390 | H17: UNITED STATES | I17: New York | J17: New York City | K17: =IFERROR(INDEX(Sheet2!$C$2:$C$1132,MATCH(Sheet1!C17,Sheet1!$C$2:$C$1132,0)),"") -> 30000 | L17: =IFERROR(INDEX(Sheet2!$D$2:$D$1132,MATCH(Sheet1!C17,$C$2:$C$1132,0)),"") -> 55000 | M17: =IFERROR(INDEX($M$2:$M$1132,MATCH(B17,$B$2:$B$1132,0)),"") -> SQL, EXCEL, POWERBI, TABLEAU | N17: HIGH-LEVEL | O17: NAUKARI
A18: 17866 | B18: DATA ENGINEER | C18: MINDSPACE | D18: =IFERROR(INDEX(Sheet2!$B$2:$B$1132,MATCH(Sheet1!C18,Sheet1!$C$2:$C$1132,0)),"IDK") -> IT | E18: FULL-TIME | F18: WORK FROM OFFICE | G18: 45316 | H18: UNITED STATES | I18: Washington | J18: Seattle | K18: =IFERROR(INDEX(Sheet2!$C$2:$C$1132,MATCH(Sheet1!C18,Sheet1!$C$2:$C$1132,0)),"") -> 35000 | L18: =IFERROR(INDEX(Sheet2!$D$2:$D$1132,MATCH(Sheet1!C18,$C$2:$C$1132,0)),"") -> 70000 | M18: =IFERROR(INDEX($M$2:$M$1132,MATCH(B18,$B$2:$B$1132,0)),"") -> SQL, PYTHON, AWS, SPARK, ETL | N18: ENTRY-LEVEL | O18: MONSTER
A19: 17867 | B19: DATA SCIENTIST | C19: ALPHA TECHNOLOGIES | D19: =IFERROR(INDEX(Sheet2!$B$2:$B$1132,MATCH(Sheet1!C19,Sheet1!$C$2:$C$1132,0)),"IDK") -> IT | E19: FULL-TIME | F19: WORK FROM OFFICE | G19: 45416 | H19: UNITED STATES | I19: Illinois | J19: Chicago | K19: =IFERROR(INDEX(Sheet2!$C$2:$C$1132,MATCH(Sheet1!C19,Sheet1!$C$2:$C$1132,0)),"") -> 35000 | L19: =IFERROR(INDEX(Sheet2!$D$2:$D$1132,MATCH(Sheet1!C19,$C$2:$C$1132,0)),"") -> 70000 | M19: =IFERROR(INDEX($M$2:$M$1132,MATCH(B19,$B$2:$B$1132,0)),"") -> PYTHON, MACHINE LEARNING,PANDAS, NUMPY | N19: ENTRY-LEVEL | O19: INDEED
A20: 17868 | B20: DATA ANALYST | C20: SKILLFIED SOLUTIONS | D20: =IFERROR(INDEX(Sheet2!$B$2:$B$1132,MATCH(Sheet1!C20,Sheet1!$C$2:$C$1132,0)),"IDK") -> IT | E20: FULL-TIME | F20: WORK FROM OFFICE | G20: 45385 | H20: UNITED STATES | I20: Georgia | J20: Atlanta | K20: =IFERROR(INDEX(Sheet2!$C$2:$C$1132,MATCH(Sheet1!C20,Sheet1!$C$2:$C$1132,0)),"") -> 25000 | L20: =IFERROR(INDEX(Sheet2!$D$2:$D$1132,MATCH(Sheet1!C20,$C$2:$C$1132,0)),"") -> 60000 | M20: =IFERROR(INDEX($M$2:$M$1132,MATCH(B20,$B$2:$B$1132,0)),"") -> SQL, EXCEL, POWERBI, TABLEAU | N20: MID-LEVEL | O20: LINKEDIN
A21: 17869 | B21: DATA ANALYST | C21: MACROS PVT LTD | D21: =IFERROR(INDEX(Sheet2!$B$2:$B$1132,MATCH(Sheet1!C21,Sheet1!$C$2:$C$1132,0)),"IDK") -> IT | E21: FULL-TIME | F21: HYBRID | G21: 45478 | H21: EUROPE | I21: United Kingdom | J21: London | K21: =IFERROR(INDEX(Sheet2!$C$2:$C$1132,MATCH(Sheet1!C21,Sheet1!$C$2:$C$1132,0)),"") -> 25000 | L21: =IFERROR(INDEX(Sheet2!$D$2:$D$1132,MATCH(Sheet1!C21,$C$2:$C$1132,0)),"") -> 75000 | M21: =IFERROR(INDEX($M$2:$M$1132,MATCH(B21,$B$2:$B$1132,0)),"") -> SQL, EXCEL, POWERBI, TABLEAU | N21: MID-LEVEL | O21: NAUKARI
A22: 17870 | B22: DATA ANALYST | C22: INFROSOFT | D22: =IFERROR(INDEX(Sheet2!$B$2:$B$1132,MATCH(Sheet1!C22,Sheet1!$C$2:$C$1132,0)),"IDK") -> SOCIAL | E22: FULL-TIME | F22: WORK FROM OFFICE | G22: 45566 | H22: EUROPE | I22: United Kingdom | J22: Manchester | K22: =IFERROR(INDEX(Sheet2!$C$2:$C$1132,MATCH(Sheet1!C22,Sheet1!$C$2:$C$1132,0)),"") -> 20000 | L22: =IFERROR(INDEX(Sheet2!$D$2:$D$1132,MATCH(Sheet1!C22,$C$2:$C$1132,0)),"") -> 70000 | M22: =IFERROR(INDEX($M$2:$M$1132,MATCH(B22,$B$2:$B$1132,0)),"") -> SQL, EXCEL, POWERBI, TABLEAU | N22: MID-LEVEL | O22: INDEED
A23: 17871 | B23: DATA ANALYST | C23: INFRATECH LTD | D23: =IFERROR(INDEX(Sheet2!$B$2:$B$1132,MATCH(Sheet1!C23,Sheet1!$C$2:$C$1132,0)),"IDK") -> FINANCE | E23: FULL-TIME | F23: WORK FROM HOME | G23: 45593 | H23: EUROPE | I23: Germany | J23: Berlin | K23: =IFERROR(INDEX(Sheet2!$C$2:$C$1132,MATCH(Sheet1!C23,Sheet1!$C$2:$C$1132,0)),"") -> 40000 | L23: =IFERROR(INDEX(Sheet2!$D$2:$D$1132,MATCH(Sheet1!C23,$C$2:$C$1132,0)),"") -> 85000 | M23: =IFERROR(INDEX($M$2:$M$1132,MATCH(B23,$B$2:$B$1132,0)),"") -> SQL, EXCEL, POWERBI, TABLEAU | N23: MID-LEVEL | O23: MONSTER
A24: 17872 | B24: DATA ANALYST | C24: ALPHA TECHNOLOGIES | D24: =IFERROR(INDEX(Sheet2!$B$2:$B$1132,MATCH(Sheet1!C24,Sheet1!$C$2:$C$1132,0)),"IDK") -> IT | E24: FULL-TIME | F24: HYBRID | G24: 45371 | H24: EUROPE | I24: Germany | J24: Munich | K24: =IFERROR(INDEX(Sheet2!$C$2:$C$1132,MATCH(Sheet1!C24,Sheet1!$C$2:$C$1132,0)),"") -> 35000 | L24: =IFERROR(INDEX(Sheet2!$D$2:$D$1132,MATCH(Sheet1!C24,$C$2:$C$1132,0)),"") -> 70000 | M24: =IFERROR(INDEX($M$2:$M$1132,MATCH(B24,$B$2:$B$1132,0)),"") -> SQL, EXCEL, POWERBI, TABLEAU | N24: MID-LEVEL | O24: GLASSDOOR
A25: 17873 | B25: DATA ANALYST | C25: CSV HEALTH | D25: =IFERROR(INDEX(Sheet2!$B$2:$B$1132,MATCH(Sheet1!C25,Sheet1!$C$2:$C$1132,0)),"IDK") -> HEALTH | E25: FULL-TIME | F25: HYBRID | G25: 45433 | H25: EUROPE | I25: France | J25: Paris | K25: =IFERROR(INDEX(Sheet2!$C$2:$C$1132,MATCH(Sheet1!C25,Sheet1!$C$2:$C$1132,0)),"") -> 25000 | L25: =IFERROR(INDEX(Sheet2!$D$2:$D$1132,MATCH(Sheet1!C25,$C$2:$C$1132,0)),"") -> 50000 | M25: =IFERROR(INDEX($M$2:$M$1132,MATCH(B25,$B$2:$B$1132,0)),"") -> SQL, EXCEL, POWERBI, TABLEAU | N25: MID-LEVEL | O25: INDEED
A26: 17874 | B26: DATA ANALYST | C26: FACEBOOK | D26: =IFERROR(INDEX(Sheet2!$B$2:$B$1132,MATCH(Sheet1!C26,Sheet1!$C$2:$C$1132,0)),"IDK") -> SOCIAL | E26: FULL-TIME | F26: HYBRID | G26: 45332 | H26: EUROPE | I26: Netherlands | J26: Amsterdam | K26: =IFERROR(INDEX(Sheet2!$C$2:$C$1132,MATCH(Sheet1!C26,Sheet1!$C$2:$C$1132,0)),"") -> 30000 | L26: =IFERROR(INDEX(Sheet2!$D$2:$D$1132,MATCH(Sheet1!C26,$C$2:$C$1132,0)),"") -> 60000 | M26: =IFERROR(INDEX($M$2:$M$1132,MATCH(B26,$B$2:$B$1132,0)),"") -> SQL, EXCEL, POWERBI, TABLEAU | N26: MID-LEVEL | O26: LINKEDIN
... A61: 17909 | B61: BUSINESS ANALYST | C61: STIER SOLUTIONS | D61: =IFERROR(INDEX(Sheet2!$B$2:$B$1132,MATCH(Sheet1!C61,Sheet1!$C$2:$C$1132,0)),"IDK") -> FINANCE | E61: INTERNSHIP | F61: HYBRID | G61: 45586 | H61: EUROPE | I61: United Kingdom | J61: Manchester | K61: =IFERROR(INDEX(Sheet2!$C$2:$C$1132,MATCH(Sheet1!C61,Sheet1!$C$2:$C$1132,0)),"") -> 35000 | L61: =IFERROR(INDEX(Sheet2!$D$2:$D$1132,MATCH(Sheet1!C61,$C$2:$C$1132,0)),"") -> 75000 | M61: =IFERROR(INDEX($M$2:$M$1132,MATCH(B61,$B$2:$B$1132,0)),"") -> EXCEL, SQL, TABLEAU, BUSINESS ANALYSIS | N61: ENTRY-LEVEL | O61: NAUKARI
A62: 17910 | B62: BUSINESS ANALYST | C62: LINKEDIN | D62: SOCIAL | E62: INTERNSHIP | F62: HYBRID | G62: 45605 | H62: EUROPE | I62: Germany | J62: Berlin | K62: 25000 | L62: 90000 | M62: =IFERROR(INDEX($M$2:$M$1132,MATCH(B62,$B$2:$B$1132,0)),"") -> EXCEL, SQL, TABLEAU, BUSINESS ANALYSIS | N62: MID-LEVEL | O62: INDEED
A63: 17911 | B63: BUSINESS ANALYST | C63: STAR HEALTH | D63: HEALTH | E63: INTERNSHIP | F63: HYBRID | G63: 45599 | H63: EUROPE | I63: Germany | J63: Munich | K63: 25000 | L63: 85000 | M63: =IFERROR(INDEX($M$2:$M$1132,MATCH(B63,$B$2:$B$1132,0)),"") -> EXCEL, SQL, TABLEAU, BUSINESS ANALYSIS | N63: HIGH-LEVEL | O63: MONSTER
A64: 17912 | B64: BUSINESS ANALYST | C64: LIC | D64: HEALTH | E64: INTERNSHIP | F64: HYBRID | G64: 45540 | H64: EUROPE | I64: France | J64: Paris | K64: 25000 | L64: 95000 | M64: =IFERROR(INDEX($M$2:$M$1132,MATCH(B64,$B$2:$B$1132,0)),"") -> EXCEL, SQL, TABLEAU, BUSINESS ANALYSIS | N64: MID-LEVEL | O64: GLASSDOOR
A65: 17913 | B65: BUSINESS ANALYST | C65: LIC | D65: HEALTH | E65: INTERNSHIP | F65: HYBRID | G65: 45452 | H65: AUSTRALIA | I65: New South Wales | J65: Sydney | K65: 25000 | L65: 95000 | M65: =IFERROR(INDEX($M$2:$M$1132,MATCH(B65,$B$2:$B$1132,0)),"") -> EXCEL, SQL, TABLEAU, BUSINESS ANALYSIS | N65: HIGH-LEVEL | O65: INDEED
A66: 17914 | B66: BUSINESS ANALYST | C66: LIC | D66: HEALTH | E66: INTERNSHIP | F66: HYBRID | G66: 45512 | H66: AUSTRALIA | I66: Victoria | J66: Melbourne | K66: 25000 | L66: 95000 | M66: =IFERROR(INDEX($M$2:$M$1132,MATCH(B66,$B$2:$B$1132,0)),"") -> EXCEL, SQL, TABLEAU, BUSINESS ANALYSIS | N66: ENTRY-LEVEL | O66: LINKEDIN
A67: 17915 | B67: DATA ANALYST | C67: LIC | D67: HEALTH | E67: INTERNSHIP | F67: HYBRID | G67: 45640 | H67: AUSTRALIA | I67: Queensland | J67: Brisbane | K67: 25000 | L67: 95000 | M67: =IFERROR(INDEX($M$2:$M$1132,MATCH(B67,$B$2:$B$1132,0)),"") -> SQL, EXCEL, POWERBI, TABLEAU | N67: HIGH-LEVEL | O67: NAUKARI
A68: 17916 | B68: DATA ENGINEER | C68: LIC | D68: HEALTH | E68: INTERNSHIP | F68: HYBRID | G68: 45617 | H68: AUSTRALIA | I68: Western Australia | J68: Perth | K68: 25000 | L68: 95000 | M68: =IFERROR(INDEX($M$2:$M$1132,MATCH(B68,$B$2:$B$1132,0)),"") -> SQL, PYTHON, AWS, SPARK, ETL | N68: HIGH-LEVEL | O68: MONSTER
A69: 17917 | B69: DATA SCIENTIST | C69: LIC | D69: HEALTH | E69: INTERNSHIP | F69: HYBRID | G69: 45395 | H69: AUSTRALIA | I69: South Australia | J69: Adelaide | K69: 25000 | L69: 95000 | M69: =IFERROR(INDEX($M$2:$M$1132,MATCH(B69,$B$2:$B$1132,0)),"") -> PYTHON, MACHINE LEARNING,PANDAS, NUMPY | N69: HIGH-LEVEL | O69: INDEED
A70: 17918 | B70: BUSINESS ANALYST | C70: LIC | D70: HEALTH | E70: INTERNSHIP | F70: HYBRID | G70: 45409 | H70: AUSTRALIA | I70: Australian Capital Territory | J70: Canberra | K70: 25000 | L70: 95000 | M70: =IFERROR(INDEX($M$2:$M$1132,MATCH(B70,$B$2:$B$1132,0)),"") -> EXCEL, SQL, TABLEAU, BUSINESS ANALYSIS | N70: HIGH-LEVEL | O70: LINKEDIN
A71: 17919 | B71: FINANCIAL ANALYST | C71: LIC | D71: HEALTH | E71: INTERNSHIP | F71: HYBRID | G71: 45481 | H71: AUSTRALIA | I71: New South Wales | J71: Sydney | K71: 25000 | L71: 95000 | M71: =IFERROR(INDEX($M$2:$M$1132,MATCH(B71,$B$2:$B$1132,0)),"") -> EXCEL, SQL, FINANCIAL MODELLING, BUDGETING | N71: HIGH-LEVEL | O71: NAUKARI
A72: 17920 | B72: CYBER SECURITY | C72: LIC | D72: HEALTH | E72: INTERNSHIP | F72: HYBRID | G72: 45426 | H72: AUSTRALIA | I72: Victoria | J72: Melbourne | K72: 25000 | L72: 95000 | M72: =IFERROR(INDEX($M$2:$M$1132,MATCH(B72,$B$2:$B$1132,0)),"") -> NETWORK SECURITY, ETHICAL HACKING, RISK ASSESSMENT | N72: ENTRY-LEVEL | O72: INDEED
A73: 17921 | B73: AI/ML ENGINEER | C73: LIC | D73: HEALTH | E73: INTERNSHIP | F73: HYBRID | G73: 45416 | H73: AUSTRALIA | I73: Queensland | J73: Brisbane | K73: 25000 | L73: 95000 | M73: =IFERROR(INDEX($M$2:$M$1132,MATCH(B73,$B$2:$B$1132,0)),"") -> CLOUD, NETWORK, MACHINE LEARNING | N73: ENTRY-LEVEL | O73: MONSTER
... A100: 17948 | B100: CYBER SECURITY | C100: LIC | D100: HEALTH | E100: INTERNSHIP | F100: HYBRID | G100: 45541 | H100: AUSTRALIA | I100: New South Wales | J100: Sydney | K100: 25000 | L100: 95000 | M100: =IFERROR(INDEX($M$2:$M$1132,MATCH(B100,$B$2:$B$1132,0)),"") -> NETWORK SECURITY, ETHICAL HACKING, RISK ASSESSMENT | N100: ENTRY-LEVEL | O100: LINKEDIN
...

Sheet Sheet2
A1: COMPANY NAME | B1: INDUSTRY | C1: SALARY MIN | D1: SALARY MAX
A2: ALPHA TECHNOLOGIES | B2: IT | C2: 35000 | D2: 70000
A3: CSV HEALTH | B3: HEALTH | C3: 25000 | D3: 50000
A4: FACEBOOK | B4: SOCIAL | C4: 30000 | D4: 60000
A5: STIER SOLUTIONS | B5: FINANCE | C5: 35000 | D5: 75000
A6: OPTUM | B6: IT | C6: 40000 | D6: 80000
A7: TECUMEN LIMITED | B7: IT | C7: 30000 | D7: 55000
A8: MINDSPACE | B8: IT | C8: 35000 | D8: 70000
A9: SKILLFIED SOLUTIONS | B9: IT | C9: 25000 | D9: 60000
A10: MACROS PVT LTD | B10: IT | C10: 25000 | D10: 75000
A11: INFROSOFT | B11: SOCIAL | C11: 20000 | D11: 70000
A12: INFRATECH LTD | B12: FINANCE | C12: 40000 | D12: 85000
A13: SCALE AI SOLUTIONS | B13: IT | C13: 35000 | D13: 90000
... A18: LINKEDIN | B18: SOCIAL | C18: 45000 | D18: 90000

Sheet Sheet3
